Workbook

Sheet Assumptions
A1: ASSUMPTIONS BLOCK - owner: replace yellow cells. Low = best case (few hours, cheap kit); High = worst case.
A2: Parameter | B2: Low | C2: Typical | D2: High | E2: Note / source
A3: VAT rate (ASSUMPTION - confirm) | B3: 0.18 | C3: 0.18 | D3: 0.18 | E3: Israeli VAT 18% assumed; confirm with accountant
A4: FX ILS per USD (ASSUMPTION) | B4: 3.7 | C4: 3.7 | D4: 3.7 | E4: Placeholder; replace with bank rate
A5: Security key list price USD | B5: 58 | C5: 64 | D5: 70 | E5: YubiKey 5C NFC: US$58.00 Staples (Oct 2026); US$63.80 incl. GST Yubico AU store; high = allowance
A6: Key landed-cost factor (shipping, import, handling) | B6: 1 | C6: 1.25 | D6: 1.45 | E6: ASSUMPTION; replace with Israeli supplier quote
A7: Router cost ILS (Inner Circle) | B7: 400 | C7: 800 | D7: 1500 | E7: ASSUMPTION; owner supplier price
A8: Price gross incl. VAT - Assessment ILS | B8: 3600 | C8: 3600 | D8: 3600 | E8: facts.json
A9: Price gross incl. VAT - Personal Shield ILS | B9: 14000 | C9: 14000 | D9: 14000 | E9: facts.json
A10: Price gross incl. VAT - Inner Circle (from) ILS | B10: 42000 | C10: 42000 | D10: 42000 | E10: facts.json
A11: Urgent surcharge gross ILS (ordinary) | B11: 4800 | C11: 4800 | D11: 4800 | E11: facts.json; weekend 6,000
A12: Keys per engagement - Assessment | B12: 0 | C12: 0 | D12: 0 | E12: -
A13: Keys per engagement - Shield | B13: 2 | C13: 2 | D13: 2 | E13: facts.json
A14: Keys per engagement - Inner Circle | B14: 8 | C14: 8 | D14: 8 | E14: facts.json
A15: HOURS (low/typ/high are owner estimates; Shield 'work' 7-14 and Assessment 4h onsite anchored to site copy)
A16: A onsite | B16: 3.5 | C16: 4 | D16: 5 | E16: stated typically 4h
A17: A travel (round trip) | B17: 1 | C17: 2 | D17: 3 | E17: ASSUMPTION Central Israel
A18: A preparation | B18: 0.5 | C18: 0.75 | D18: 1 | E18: ASSUMPTION
A19: A write-up / summary | B19: 1 | C19: 1.5 | D19: 2.5 | E19: ASSUMPTION; client gets practical summary
A20: A support / messages | B20: 0.25 | C20: 0.5 | D20: 1 | E20: ASSUMPTION
A21: S work (onsite+remote config) | B21: 7 | C21: 10.5 | D21: 14 | E21: stated 7-14 h excl. Assessment
A22: S travel | B22: 2 | C22: 4 | D22: 6 | E22: ASSUMPTION 1-3 visits
A23: S preparation (incl. key ordering/provisioning) | B23: 1 | C23: 2 | D23: 3 | E23: ASSUMPTION
A24: S write-up / handover | B24: 1 | C24: 2 | D24: 3 | E24: ASSUMPTION
A25: S 14-day adjustment support | B25: 1 | C25: 2 | D25: 4 | E25: ASSUMPTION
A26: I work (2-4 days x 8h) | B26: 16 | C26: 24 | D26: 32 | E26: stated 2-4 working days
A27: I travel | B27: 4 | C27: 6 | D27: 10 | E27: ASSUMPTION
... A30: I adjustment support | B30: 3 | C30: 6 | D30: 10 | E30: ASSUMPTION (support term for IC not stated in facts)
A31: CAPACITY
A32: Delivery hours per month (net of sales/admin/leave) | B32: 90 | C32: 120 | D32: 140 | E32: OWNER INPUT
A33: Owner target net hourly value ILS (placeholder) | B33: 500 | C33: 700 | D33: 900 | E33: OWNER INPUT - placeholder only

Sheet Model
A1: Scenario (hours AND kit cost move together) | B1: Low hours / best | C1: Typical | D1: High hours / worst | E1: Note
A2: Assessment (standalone)
A3: A gross price | B3: =Assumptions!B8 | C3: =Assumptions!C8 | D3: =Assumptions!D8
A4: A net revenue | B4: =B3/(1+Assumptions!B3) | C4: =C3/(1+Assumptions!C3) | D4: =D3/(1+Assumptions!D3)
A5: A total hours | B5: =SUM(Assumptions!B16:B20) | C5: =SUM(Assumptions!C16:C20) | D5: =SUM(Assumptions!D16:D20)
A6: A contribution (no hardware) | B6: =B4 | C6: =C4 | D6: =D4
A7: A net ILS per hour | B7: =B6/B5 | C7: =C6/C5 | D7: =D6/D5
A8: Personal Shield (no prior Assessment, full 14,000)
A9: S gross price | B9: =Assumptions!B9 | C9: =Assumptions!C9 | D9: =Assumptions!D9
A10: S net revenue | B10: =B9/(1+Assumptions!B3) | C10: =C9/(1+Assumptions!C3) | D10: =D9/(1+Assumptions!D3)
A11: S total hours | B11: =SUM(Assumptions!B21:B25) | C11: =SUM(Assumptions!C21:C25) | D11: =SUM(Assumptions!D21:D25)
A12: S hardware (2 keys) | B12: =Assumptions!B13*(Assumptions!B5*Assumptions!B4*Assumptions!B6) | C12: =Assumptions!C13*(Assumptions!C5*Assumptions!C4*Assumptions!C6) | D12: =Assumptions!D13*(Assumptions!D5*Assumptions!D4*Assumptions!D6)
A13: S contribution after hardware | B13: =B10-B12 | C13: =C10-C12 | D13: =D10-D12
A14: S net ILS/hour before hardware | B14: =B10/B11 | C14: =C10/C11 | D14: =D10/D11
A15: S net ILS/hour after hardware | B15: =B13/B11 | C15: =C13/C11 | D15: =D13/D11
A16: Inner Circle (from 42,000)
A17: I gross price | B17: =Assumptions!B10 | C17: =Assumptions!C10 | D17: =Assumptions!D10
A18: I net revenue | B18: =B17/(1+Assumptions!B3) | C18: =C17/(1+Assumptions!C3) | D18: =D17/(1+Assumptions!D3)
A19: I total hours | B19: =SUM(Assumptions!B26:B30) | C19: =SUM(Assumptions!C26:C30) | D19: =SUM(Assumptions!D26:D30)
A20: I hardware (8 keys + router) | B20: =Assumptions!B14*(Assumptions!B5*Assumptions!B4*Assumptions!B6)+Assumptions!B7 | C20: =Assumptions!C14*(Assumptions!C5*Assumptions!C4*Assumptions!C6)+Assumptions!C7 | D20: =Assumptions!D14*(Assumptions!D5*Assumptions!D4*Assumptions!D6)+Assumptions!D7
A21: I contribution after hardware | B21: =B18-B20 | C21: =C18-C20 | D21: =D18-D20
A22: I net ILS/hour before hardware | B22: =B18/B19 | C22: =C18/C19 | D22: =D18/D19
A23: I net ILS/hour after hardware | B23: =B21/B19 | C23: =C21/C19 | D23: =D21/D19
A24: Assessment-credit paths (Assessment then full service within 14 days; total cash = full-service price)
A25: Shield path: total net revenue (credited) | B25: =B10 | C25: =C10 | D25: =D10
A26: Shield path: total hours (A+S) | B26: =B5+B11 | C26: =C5+C11 | D26: =D5+D11
A27: Shield path: contribution after hardware | B27: =B25-B12 | C27: =C25-C12 | D27: =D25-D12
A28: Shield path: net ILS/hour after hardware | B28: =B27/B26 | C28: =C27/C26 | D28: =D27/D26
A29: Shield path if NOT credited: net ILS/hour after hardware | B29: =(B10+B4-B12)/B26 | C29: =(C10+C4-C12)/C26 | D29: =(D10+D4-D12)/D26
A30: Net revenue given up by credit (ILS) | B30: =B4 | C30: =C4 | D30: =D4
A31: Hourly-rate cost of credit (ILS/h) | B31: =B29-B28 | C31: =C29-C28 | D31: =D29-D28
A32: Inner Circle path: contribution after hardware | B32: =B18-B20 | C32: =C18-C20 | D32: =D18-D20
A33: Inner Circle path: total hours (A+I) | B33: =B5+B19 | C33: =C5+C19 | D33: =D5+D19
A34: Inner Circle path: net ILS/hour after hardware | B34: =B32/B33 | C34: =C32/C33 | D34: =D32/D33
A35: Urgent surcharge (net)
A36: Surcharge net revenue | B36: =Assumptions!B11/(1+Assumptions!B3) | C36: =Assumptions!C11/(1+Assumptions!C3) | D36: =Assumptions!D11/(1+Assumptions!D3)
A37: Capacity (typical-hours engagements per month; engagement hours held at typical; columns = capacity 90/120/140 h)
A38: Delivery hours per month | B38: =Assumptions!B32 | C38: =Assumptions!C32 | D38: =Assumptions!D32
A39: Assessments only / month | B39: =B38/$C$5 | C39: =C38/$C$5 | D39: =D38/$C$5
A40: Shield (standalone) / month | B40: =B38/$C$11 | C40: =C38/$C$11 | D40: =D38/$C$11
...

Sheet Sensitivity
A1: Net ILS/hour after hardware, typical cost; rows = hours vs typical, columns = price vs list. Offer sections below.
A3: Assessment
A4: Hours \ Price | B4: -0.2 | C4: -0.1 | D4: 0 | E4: 0.1 | F4: 0.2
A5: -0.2 | B5: =(Model!$C$4*(1+B$4))/(Model!$C$5*(1+$A5)) | C5: =(Model!$C$4*(1+C$4))/(Model!$C$5*(1+$A5)) | D5: =(Model!$C$4*(1+D$4))/(Model!$C$5*(1+$A5)) | E5: =(Model!$C$4*(1+E$4))/(Model!$C$5*(1+$A5)) | F5: =(Model!$C$4*(1+F$4))/(Model!$C$5*(1+$A5))
A6: -0.1 | B6: =(Model!$C$4*(1+B$4))/(Model!$C$5*(1+$A6)) | C6: =(Model!$C$4*(1+C$4))/(Model!$C$5*(1+$A6)) | D6: =(Model!$C$4*(1+D$4))/(Model!$C$5*(1+$A6)) | E6: =(Model!$C$4*(1+E$4))/(Model!$C$5*(1+$A6)) | F6: =(Model!$C$4*(1+F$4))/(Model!$C$5*(1+$A6))
A7: 0 | B7: =(Model!$C$4*(1+B$4))/(Model!$C$5*(1+$A7)) | C7: =(Model!$C$4*(1+C$4))/(Model!$C$5*(1+$A7)) | D7: =(Model!$C$4*(1+D$4))/(Model!$C$5*(1+$A7)) | E7: =(Model!$C$4*(1+E$4))/(Model!$C$5*(1+$A7)) | F7: =(Model!$C$4*(1+F$4))/(Model!$C$5*(1+$A7))
A8: 0.1 | B8: =(Model!$C$4*(1+B$4))/(Model!$C$5*(1+$A8)) | C8: =(Model!$C$4*(1+C$4))/(Model!$C$5*(1+$A8)) | D8: =(Model!$C$4*(1+D$4))/(Model!$C$5*(1+$A8)) | E8: =(Model!$C$4*(1+E$4))/(Model!$C$5*(1+$A8)) | F8: =(Model!$C$4*(1+F$4))/(Model!$C$5*(1+$A8))
A9: 0.2 | B9: =(Model!$C$4*(1+B$4))/(Model!$C$5*(1+$A9)) | C9: =(Model!$C$4*(1+C$4))/(Model!$C$5*(1+$A9)) | D9: =(Model!$C$4*(1+D$4))/(Model!$C$5*(1+$A9)) | E9: =(Model!$C$4*(1+E$4))/(Model!$C$5*(1+$A9)) | F9: =(Model!$C$4*(1+F$4))/(Model!$C$5*(1+$A9))
A11: Personal Shield (standalone)
A12: Hours \ Price | B12: -0.2 | C12: -0.1 | D12: 0 | E12: 0.1 | F12: 0.2
A13: -0.2 | B13: =(Model!$C$10*(1+B$12)-Model!C12)/(Model!$C$11*(1+$A13)) | C13: =(Model!$C$10*(1+C$12)-Model!C12)/(Model!$C$11*(1+$A13)) | D13: =(Model!$C$10*(1+D$12)-Model!C12)/(Model!$C$11*(1+$A13)) | E13: =(Model!$C$10*(1+E$12)-Model!C12)/(Model!$C$11*(1+$A13)) | F13: =(Model!$C$10*(1+F$12)-Model!C12)/(Model!$C$11*(1+$A13))
A14: -0.1 | B14: =(Model!$C$10*(1+B$12)-Model!C12)/(Model!$C$11*(1+$A14)) | C14: =(Model!$C$10*(1+C$12)-Model!C12)/(Model!$C$11*(1+$A14)) | D14: =(Model!$C$10*(1+D$12)-Model!C12)/(Model!$C$11*(1+$A14)) | E14: =(Model!$C$10*(1+E$12)-Model!C12)/(Model!$C$11*(1+$A14)) | F14: =(Model!$C$10*(1+F$12)-Model!C12)/(Model!$C$11*(1+$A14))
A15: 0 | B15: =(Model!$C$10*(1+B$12)-Model!C12)/(Model!$C$11*(1+$A15)) | C15: =(Model!$C$10*(1+C$12)-Model!C12)/(Model!$C$11*(1+$A15)) | D15: =(Model!$C$10*(1+D$12)-Model!C12)/(Model!$C$11*(1+$A15)) | E15: =(Model!$C$10*(1+E$12)-Model!C12)/(Model!$C$11*(1+$A15)) | F15: =(Model!$C$10*(1+F$12)-Model!C12)/(Model!$C$11*(1+$A15))
A16: 0.1 | B16: =(Model!$C$10*(1+B$12)-Model!C12)/(Model!$C$11*(1+$A16)) | C16: =(Model!$C$10*(1+C$12)-Model!C12)/(Model!$C$11*(1+$A16)) | D16: =(Model!$C$10*(1+D$12)-Model!C12)/(Model!$C$11*(1+$A16)) | E16: =(Model!$C$10*(1+E$12)-Model!C12)/(Model!$C$11*(1+$A16)) | F16: =(Model!$C$10*(1+F$12)-Model!C12)/(Model!$C$11*(1+$A16))
A17: 0.2 | B17: =(Model!$C$10*(1+B$12)-Model!C12)/(Model!$C$11*(1+$A17)) | C17: =(Model!$C$10*(1+C$12)-Model!C12)/(Model!$C$11*(1+$A17)) | D17: =(Model!$C$10*(1+D$12)-Model!C12)/(Model!$C$11*(1+$A17)) | E17: =(Model!$C$10*(1+E$12)-Model!C12)/(Model!$C$11*(1+$A17)) | F17: =(Model!$C$10*(1+F$12)-Model!C12)/(Model!$C$11*(1+$A17))
A19: Shield path (A+S, credited)
A20: Hours \ Price | B20: -0.2 | C20: -0.1 | D20: 0 | E20: 0.1 | F20: 0.2
A21: -0.2 | B21: =(Model!$C$25*(1+B$20)-Model!C12)/(Model!$C$26*(1+$A21)) | C21: =(Model!$C$25*(1+C$20)-Model!C12)/(Model!$C$26*(1+$A21)) | D21: =(Model!$C$25*(1+D$20)-Model!C12)/(Model!$C$26*(1+$A21)) | E21: =(Model!$C$25*(1+E$20)-Model!C12)/(Model!$C$26*(1+$A21)) | F21: =(Model!$C$25*(1+F$20)-Model!C12)/(Model!$C$26*(1+$A21))
A22: -0.1 | B22: =(Model!$C$25*(1+B$20)-Model!C12)/(Model!$C$26*(1+$A22)) | C22: =(Model!$C$25*(1+C$20)-Model!C12)/(Model!$C$26*(1+$A22)) | D22: =(Model!$C$25*(1+D$20)-Model!C12)/(Model!$C$26*(1+$A22)) | E22: =(Model!$C$25*(1+E$20)-Model!C12)/(Model!$C$26*(1+$A22)) | F22: =(Model!$C$25*(1+F$20)-Model!C12)/(Model!$C$26*(1+$A22))
A23: 0 | B23: =(Model!$C$25*(1+B$20)-Model!C12)/(Model!$C$26*(1+$A23)) | C23: =(Model!$C$25*(1+C$20)-Model!C12)/(Model!$C$26*(1+$A23)) | D23: =(Model!$C$25*(1+D$20)-Model!C12)/(Model!$C$26*(1+$A23)) | E23: =(Model!$C$25*(1+E$20)-Model!C12)/(Model!$C$26*(1+$A23)) | F23: =(Model!$C$25*(1+F$20)-Model!C12)/(Model!$C$26*(1+$A23))
A24: 0.1 | B24: =(Model!$C$25*(1+B$20)-Model!C12)/(Model!$C$26*(1+$A24)) | C24: =(Model!$C$25*(1+C$20)-Model!C12)/(Model!$C$26*(1+$A24)) | D24: =(Model!$C$25*(1+D$20)-Model!C12)/(Model!$C$26*(1+$A24)) | E24: =(Model!$C$25*(1+E$20)-Model!C12)/(Model!$C$26*(1+$A24)) | F24: =(Model!$C$25*(1+F$20)-Model!C12)/(Model!$C$26*(1+$A24))
A25: 0.2 | B25: =(Model!$C$25*(1+B$20)-Model!C12)/(Model!$C$26*(1+$A25)) | C25: =(Model!$C$25*(1+C$20)-Model!C12)/(Model!$C$26*(1+$A25)) | D25: =(Model!$C$25*(1+D$20)-Model!C12)/(Model!$C$26*(1+$A25)) | E25: =(Model!$C$25*(1+E$20)-Model!C12)/(Model!$C$26*(1+$A25)) | F25: =(Model!$C$25*(1+F$20)-Model!C12)/(Model!$C$26*(1+$A25))
A27: Inner Circle (standalone)
A28: Hours \ Price | B28: -0.2 | C28: -0.1 | D28: 0 | E28: 0.1 | F28: 0.2
A29: -0.2 | B29: =(Model!$C$18*(1+B$28)-Model!C20)/(Model!$C$19*(1+$A29)) | C29: =(Model!$C$18*(1+C$28)-Model!C20)/(Model!$C$19*(1+$A29)) | D29: =(Model!$C$18*(1+D$28)-Model!C20)/(Model!$C$19*(1+$A29)) | E29: =(Model!$C$18*(1+E$28)-Model!C20)/(Model!$C$19*(1+$A29)) | F29: =(Model!$C$18*(1+F$28)-Model!C20)/(Model!$C$19*(1+$A29))
A30: -0.1 | B30: =(Model!$C$18*(1+B$28)-Model!C20)/(Model!$C$19*(1+$A30)) | C30: =(Model!$C$18*(1+C$28)-Model!C20)/(Model!$C$19*(1+$A30)) | D30: =(Model!$C$18*(1+D$28)-Model!C20)/(Model!$C$19*(1+$A30)) | E30: =(Model!$C$18*(1+E$28)-Model!C20)/(Model!$C$19*(1+$A30)) | F30: =(Model!$C$18*(1+F$28)-Model!C20)/(Model!$C$19*(1+$A30))
A31: 0 | B31: =(Model!$C$18*(1+B$28)-Model!C20)/(Model!$C$19*(1+$A31)) | C31: =(Model!$C$18*(1+C$28)-Model!C20)/(Model!$C$19*(1+$A31)) | D31: =(Model!$C$18*(1+D$28)-Model!C20)/(Model!$C$19*(1+$A31)) | E31: =(Model!$C$18*(1+E$28)-Model!C20)/(Model!$C$19*(1+$A31)) | F31: =(Model!$C$18*(1+F$28)-Model!C20)/(Model!$C$19*(1+$A31))
A32: 0.1 | B32: =(Model!$C$18*(1+B$28)-Model!C20)/(Model!$C$19*(1+$A32)) | C32: =(Model!$C$18*(1+C$28)-Model!C20)/(Model!$C$19*(1+$A32)) | D32: =(Model!$C$18*(1+D$28)-Model!C20)/(Model!$C$19*(1+$A32)) | E32: =(Model!$C$18*(1+E$28)-Model!C20)/(Model!$C$19*(1+$A32)) | F32: =(Model!$C$18*(1+F$28)-Model!C20)/(Model!$C$19*(1+$A32))
A33: 0.2 | B33: =(Model!$C$18*(1+B$28)-Model!C20)/(Model!$C$19*(1+$A33)) | C33: =(Model!$C$18*(1+C$28)-Model!C20)/(Model!$C$19*(1+$A33)) | D33: =(Model!$C$18*(1+D$28)-Model!C20)/(Model!$C$19*(1+$A33)) | E33: =(Model!$C$18*(1+E$28)-Model!C20)/(Model!$C$19*(1+$A33)) | F33: =(Model!$C$18*(1+F$28)-Model!C20)/(Model!$C$19*(1+$A33))

Sheet Tier-economics
A1: Check | B1: Value | C1: Note
A2: Shield gross per person | B2: =Assumptions!C9/1
A3: Inner Circle gross per person (from) | B3: =Assumptions!C10/4
A4: IC per-person vs Shield (ratio) | B4: =B3/B2 | C4: <1 = group discount
A5: IC / Shield total price ratio | B5: =Assumptions!C10/Assumptions!C9 | C5: for 4x people, 4x devices, 4x keys
A6: Shield gross per device | B6: =Assumptions!C9/2
A7: IC gross per device | B7: =Assumptions!C10/8
A8: Shield gross per key slot | B8: =Assumptions!C9/2 | C8: bundled with labour
A9: Assessment as % of Shield | B9: =Assumptions!C8/Assumptions!C9
A10: Assessment as % of IC | B10: =Assumptions!C8/Assumptions!C10
A11: Shield remaining after credit | B11: =Assumptions!C9-Assumptions!C8
A12: IC remaining after credit (from) | B12: =Assumptions!C10-Assumptions!C8
A13: IC remaining per person after credit | B13: =B12/4
A14: Urgent surcharge as % of Assessment (ordinary) | B14: =Assumptions!C11/Assumptions!C8
A15: Typical hours ratio IC/Shield | B15: =Model!C19/Model!C11
A16: Typical net/hr ratio IC/Shield (after hardware) | B16: =Model!C23/Model!C15
A17: BESPOKE floor: days | C17: Inputs below (owner can edit yellow)
A18: Bespoke design: delivery days (8h work) | B18: 6 | C18: option; IC top is 4 days
A19: Bespoke work hours | B19: =B18*8
A20: Bespoke travel+prep+write-up+support hours (ratio of work hrs, from IC typical) | B20: =(Model!C19-Assumptions!C26)/Assumptions!C26 | C20: overhead ratio
A21: Bespoke total hours | B21: =B19*(1+B20)
A22: Bespoke hardware allowance ILS | B22: 3000 | C22: placeholder
A23: Floor net price at Shield-typical net/hr rate | B23: =B21*Model!C15+B22 | C23: net of VAT
A24: gross incl. VAT | B24: =B23*(1+Assumptions!C3)
A25: Floor net price at IC-typical net/hr rate | B25: =B21*Model!C23+B22
A26: gross incl. VAT | B26: =B25*(1+Assumptions!C3)
A27: Floor net price at owner target hourly (typical) | B27: =B21*Assumptions!C33+B22
A28: gross incl. VAT | B28: =B27*(1+Assumptions!C3)
